Workbook

Sheet Léeme
A1: FINANZAS FAMILIARES — plantilla con datos de ejemplo
A2: Todas las cifras son INVENTADAS (una familia ficticia: Ana, Luis y su hijo Leo). Sustitúyelas por las tuyas.
A4: QUÉ HAY DENTRO
A5: Dos partes que se alimentan solas:
A6: • FINANZAS (lo que tienes hoy): Patrimonio Neto, Ingresos - Gastos, Presupuesto, Gráficos, Fondo de emergencia.
A7: • PLAN (a dónde quieres llegar): Panel, Objetivos, Proyección. Lee tu ahorro y lo ya invertido de la parte de finanzas.
A9: EN QUÉ ORDEN RELLENARLO
A10: 1. Patrimonio Neto — lo que tienes y lo que debes. Pon la FECHA de hoy en E1: los plazos de los objetivos se cuentan desde ese año.
A11: 2. Ingresos - Gastos — cada concepto en la columna B (si es mensual) o en la C (si es anual), nunca en las dos. La G es para tus notas.
A12: Truco: saca los importes del extracto del banco de los últimos 12 meses; los recibos anuales o estacionales (IBI, seguros, gas) mejor en anual.
A13: 3. Presupuesto — la columna D (en azul) es lo que QUIERES gastar. El resto se copia solo de «Ingresos - Gastos».
A14: 4. Fondo de emergencia — cuánto aguantaríais sin ingresos. Rellena el paro estimado y los recortes que harías.
... A40: • No incluye la pensión pública: el objetivo de jubilación es el COMPLEMENTO que quieres añadirle.

Sheet Patrimonio Neto
A1: PATRIMONIO NETO | D1: Última actualización | E1: 46266
A2: Lo que tienes menos lo que debes. CIFRAS INVENTADAS: pon las tuyas y actualiza la fecha de E1 (los plazos de «Objetivos» se cuentan desde ese año).
A3: PATRIMONIO NETO (Activos − Pasivos) | E3: =E5-E17 -> 146200
A5: ACTIVOS (BIENES) | E5: =SUM(E7:E15) -> 311200
A6: Descripción | B6: Entidad | C6: Nº de cuenta | D6: Titular/es | E6: Valoración
A7: Vivienda habitual | D7: Ana 50% / Luis 50% | E7: 260000 | G7: EJEMPLO. Valor estimado de mercado hoy (no el de compra). La hipoteca va abajo, en pasivos
A8: Cuenta corriente común | B8: Banco A | C8: *1234 | D8: Común | E8: 4500 | G8: EJEMPLO. La del día a día: aquí entran las nóminas y salen los recibos
A9: Cuenta remunerada (colchón) | B9: Banco B | D9: Común | E9: 14000 | G9: EJEMPLO. Fondo de emergencia, separado de la cuenta del día a día para no tocarlo
A10: Cuenta personal Ana | D10: Ana | E10: 1500
A11: Cuenta personal Luis | D11: Luis | E11: 1200
A12: Cartera conservadora | B12: Gestora X | D12: Común | E12: 3000 | G12: EJEMPLO. Dinero para objetivos a menos de ~10 años. La pestaña «Objetivos» lee de aquí lo ya invertido
A13: Cartera indexada global | B13: Gestora Y | D13: Común | E13: 18000 | G13: EJEMPLO. Dinero para objetivos lejanos (15+ años). La pestaña «Objetivos» lee de aquí lo ya invertido
A14: Plan de pensiones | B14: Gestora Z | D14: Luis | E14: 9000 | G14: EJEMPLO. No es dinero disponible: solo se rescata en los supuestos que marca la ley
A17: PASIVOS (DEUDAS) | E17: =SUM(E19:E21) -> 165000
A18: Descripción | B18: Entidad | C18: Nº de cuenta | D18: Titular/es | E18: Valoración
A19: Hipoteca de la vivienda | B19: Banco A | D19: Ana 50% / Luis 50% | E19: 165000 | G19: EJEMPLO. Capital pendiente (lo que aún debes), no la cuota
A23: RATIO DE ENDEUDAMIENTO | E23: =IFERROR(E17/E5,0) -> 0.53020566
A24: Deudas sobre activos. Por debajo del 40% se considera cómodo.

Sheet Ingresos - Gastos
A1: INGRESOS Y GASTOS — Familia de ejemplo (Ana, Luis y Leo)
A2: CIFRAS INVENTADAS. Sustitúyelas por las tuyas: columna B si el gasto es mensual, columna C si es anual (nunca las dos). La columna G es para apuntar de dónde sale cada dato.
A4: INGRESOS | B4: MENSUAL | C4: ANUAL | D4: TOTAL ANUAL | E4: % | G4: Origen del dato · avisos
A5: Laborales | B5: =SUM(B6:B10) -> 4040 | C5: =SUM(C6:C10) -> 1200 | D5: =SUM(D6:D10) -> 49680 | E5: =IFERROR(D5/$D$15,0) -> 0.9939976
A6: Nómina neta Ana | B6: 2100 | D6: =IF(B6>0,B6*12,C6) -> 25200 | E6: =IFERROR(D6/$D$15,0) -> 0.50420168 | G6: EJEMPLO. Lo que entra en la cuenta cada mes (neto). Si cobras pagas extra prorrateadas, pon el neto mensual; si no, pon el total anual en la columna C
A7: Nómina neta Luis | B7: 1850 | D7: =IF(B7>0,B7*12,C7) -> 22200 | E7: =IFERROR(D7/$D$15,0) -> 0.44417767 | G7: EJEMPLO. Mismo criterio que la fila de arriba
A8: Retribución flexible (seguro médico de empresa) | B8: 90 | D8: =IF(B8>0,B8*12,C8) -> 1080 | E8: =IFERROR(D8/$D$15,0) -> 0.021608643 | G8: EJEMPLO. Si la empresa te paga algo en especie (seguro, ticket, plan de pensiones), entra como ingreso y sale como gasto: así el total es honesto
A9: Ingresos extra (variable) | C9: 1200 | D9: =IF(B9>0,B9*12,C9) -> 1200 | E9: =IFERROR(D9/$D$15,0) -> 0.024009604 | G9: EJEMPLO. Freelance, bonus, ventas de segunda mano… Anual y sin inflar: solo lo que de verdad cobras
D10: =IF(B10>0,B10*12,C10) -> 0 | E10: =IFERROR(D10/$D$15,0) -> 0
A11: Inversiones | B11: =SUM(B12:B14) -> 0 | C11: =SUM(C12:C14) -> 300 | D11: =SUM(D12:D14) -> 300 | E11: =IFERROR(D11/$D$15,0) -> 0.006002401
A12: Intereses cuentas y depósitos | C12: 300 | D12: =IF(B12>0,B12*12,C12) -> 300 | E12: =IFERROR(D12/$D$15,0) -> 0.006002401 | G12: EJEMPLO. Intereses brutos al año de la cuenta remunerada (antes de la retención de Hacienda)
D13: =IF(B13>0,B13*12,C13) -> 0 | E13: =IFERROR(D13/$D$15,0) -> 0
D14: =IF(B14>0,B14*12,C14) -> 0 | E14: =IFERROR(D14/$D$15,0) -> 0
A15: TOTAL INGRESOS | D15: =D5+D11 -> 49980
A17: GASTOS | B17: MENSUAL | C17: ANUAL | D17: TOTAL ANUAL | E17: % | G17: Origen del dato · avisos
A18: INDISPENSABLES | D18: =D19+D27+D32 -> 13960 | E18: =IFERROR(D18/$D$96,0) -> 0.35962698
A19: Vivienda habitual | B19: =SUM(B20:B26) -> 820 | C19: =SUM(C20:C26) -> 880 | D19: =SUM(D20:D26) -> 10720 | E19: =IFERROR(D19/$D$96,0) -> 0.27616054
A20: Hipoteca / alquiler | B20: 750 | D20: =IF(B20>0,B20*12,C20) -> 9000 | E20: =IFERROR(D20/$D$96,0) -> 0.2318512 | G20: EJEMPLO. Cuota mensual
A21: Comunidad | B21: 70 | D21: =IF(B21>0,B21*12,C21) -> 840 | E21: =IFERROR(D21/$D$96,0) -> 0.021639446 | G21: EJEMPLO
A22: Seguro vivienda | C22: 320 | D22: =IF(B22>0,B22*12,C22) -> 320 | E22: =IFERROR(D22/$D$96,0) -> 0.0082435983 | G22: EJEMPLO. Recibo anual
A23: IBI | C23: 450 | D23: =IF(B23>0,B23*12,C23) -> 450 | E23: =IFERROR(D23/$D$96,0) -> 0.01159256 | G23: EJEMPLO. Recibo anual del ayuntamiento
A24: Tasa basuras | C24: 110 | D24: =IF(B24>0,B24*12,C24) -> 110 | E24: =IFERROR(D24/$D$96,0) -> 0.0028337369 | G24: EJEMPLO
D25: =IF(B25>0,B25*12,C25) -> 0 | E25: =IFERROR(D25/$D$96,0) -> 0
D26: =IF(B26>0,B26*12,C26) -> 0 | E26: =IFERROR(D26/$D$96,0) -> 0
A27: Seguros | B27: =SUM(B28:B31) -> 90 | C27: =SUM(C28:C31) -> 360 | D27: =SUM(D28:D31) -> 1440 | E27: =IFERROR(D27/$D$96,0) -> 0.037096192
A28: Seguro de vida | C28: 360 | D28: =IF(B28>0,B28*12,C28) -> 360 | E28: =IFERROR(D28/$D$96,0) -> 0.0092740481 | G28: EJEMPLO. Suele ir ligado a la hipoteca: revisa si cubre solo la deuda o también a la familia
A29: Seguro de salud | B29: 90 | D29: =IF(B29>0,B29*12,C29) -> 1080 | E29: =IFERROR(D29/$D$96,0) -> 0.027822144 | G29: EJEMPLO. Si te lo paga la empresa, aparece también arriba como retribución flexible
D30: =IF(B30>0,B30*12,C30) -> 0 | E30: =IFERROR(D30/$D$96,0) -> 0
D31: =IF(B31>0,B31*12,C31) -> 0 | E31: =IFERROR(D31/$D$96,0) -> 0
A32: Ahorro / Inversión | B32: =SUM(B33:B35) -> 150 | C32: =SUM(C33:C35) -> 0 | D32: =SUM(D33:D35) -> 1800 | E32: =IFERROR(D32/$D$96,0) -> 0.046370241
A33: Jubilación (plan de pensiones) | B33: 150 | D33: =IF(B33>0,B33*12,C33) -> 1800 | E33: =IFERROR(D33/$D$96,0) -> 0.046370241 | G33: EJEMPLO. Aportación mensual al plan. No es dinero disponible: por eso va aquí como gasto y no en el ahorro del final. La pestaña «Panel» la lee de esta fila
D34: =IF(B34>0,B34*12,C34) -> 0 | E34: =IFERROR(D34/$D$96,0) -> 0
D35: =IF(B35>0,B35*12,C35) -> 0 | E35: =IFERROR(D35/$D$96,0) -> 0
A37: NECESARIOS | D37: =D38+D46+D51+D57+D64 -> 18590 | E37: =IFERROR(D37/$D$96,0) -> 0.47890154
A38: Recibos y servicios del hogar | B38: =SUM(B39:B45) -> 100 | C38: =SUM(C39:C45) -> 910 | D38: =SUM(D39:D45) -> 2110 | E38: =IFERROR(D38/$D$96,0) -> 0.054356226
A39: Agua | C39: 240 | D39: =IF(B39>0,B39*12,C39) -> 240 | E39: =IFERROR(D39/$D$96,0) -> 0.0061826987 | G39: EJEMPLO. Suma de los recibos del año
A40: Luz | B40: 55 | D40: =IF(B40>0,B40*12,C40) -> 660 | E40: =IFERROR(D40/$D$96,0) -> 0.017002422 | G40: EJEMPLO
A41: Gas / calefacción | C41: 420 | D41: =IF(B41>0,B41*12,C41) -> 420 | E41: =IFERROR(D41/$D$96,0) -> 0.010819723 | G41: EJEMPLO. Muy estacional: mejor el total anual
A42: Teléfono / Internet | B42: 45 | D42: =IF(B42>0,B42*12,C42) -> 540 | E42: =IFERROR(D42/$D$96,0) -> 0.013911072 | G42: EJEMPLO
A43: Mantenimiento del hogar | C43: 250 | D43: =IF(B43>0,B43*12,C43) -> 250 | E43: =IFERROR(D43/$D$96,0) -> 0.0064403112 | G43: EJEMPLO. Revisión de la caldera, pequeñas reparaciones
...

Sheet Presupuesto
A1: PRESUPUESTO
A2: Izquierda: lo que gastas hoy (viene solo de «Ingresos - Gastos», no se toca). Derecha: lo que QUIERES gastar — edita la columna D. La diferencia te dice cuánto liberas.
A4: CONCEPTO | B4: ACTUAL MENSUAL | C4: ACTUAL ANUAL | D4: PRESUPUESTO MENSUAL | E4: PRESUPUESTO ANUAL | F4: DIFERENCIA ANUAL | G4: %
A5: INDISPENSABLES | B5: =B6+B14+B19 -> 1163.3333 | C5: =C6+C14+C19 -> 13960 | D5: =D6+D14+D19 -> 1163.3333 | E5: =E6+E14+E19 -> 13960 | F5: =F6+F14+F19 -> 0 | G5: =IFERROR(E5/$E$83,0) -> 0.35962698
A6: Vivienda habitual | B6: =SUM(B7:B13) -> 893.33333 | C6: =SUM(C7:C13) -> 10720 | D6: =SUM(D7:D13) -> 893.33333 | E6: =SUM(E7:E13) -> 10720 | F6: =SUM(F7:F13) -> 0
A7: =IF('Ingresos - Gastos'!A20="","",'Ingresos - Gastos'!A20) -> Hipoteca / alquiler | B7: ='Ingresos - Gastos'!D20/12 -> 750 | C7: ='Ingresos - Gastos'!D20 -> 9000 | D7: =B7 -> 750 | E7: =D7*12 -> 9000 | F7: =C7-E7 -> 0
A8: =IF('Ingresos - Gastos'!A21="","",'Ingresos - Gastos'!A21) -> Comunidad | B8: ='Ingresos - Gastos'!D21/12 -> 70 | C8: ='Ingresos - Gastos'!D21 -> 840 | D8: =B8 -> 70 | E8: =D8*12 -> 840 | F8: =C8-E8 -> 0
A9: =IF('Ingresos - Gastos'!A22="","",'Ingresos - Gastos'!A22) -> Seguro vivienda | B9: ='Ingresos - Gastos'!D22/12 -> 26.666667 | C9: ='Ingresos - Gastos'!D22 -> 320 | D9: =B9 -> 26.666667 | E9: =D9*12 -> 320 | F9: =C9-E9 -> 0
A10: =IF('Ingresos - Gastos'!A23="","",'Ingresos - Gastos'!A23) -> IBI | B10: ='Ingresos - Gastos'!D23/12 -> 37.5 | C10: ='Ingresos - Gastos'!D23 -> 450 | D10: =B10 -> 37.5 | E10: =D10*12 -> 450 | F10: =C10-E10 -> 0
A11: =IF('Ingresos - Gastos'!A24="","",'Ingresos - Gastos'!A24) -> Tasa basuras | B11: ='Ingresos - Gastos'!D24/12 -> 9.1666667 | C11: ='Ingresos - Gastos'!D24 -> 110 | D11: =B11 -> 9.1666667 | E11: =D11*12 -> 110 | F11: =C11-E11 -> 0
A12: =IF('Ingresos - Gastos'!A25="","",'Ingresos - Gastos'!A25) | B12: ='Ingresos - Gastos'!D25/12 -> 0 | C12: ='Ingresos - Gastos'!D25 -> 0 | D12: =B12 -> 0 | E12: =D12*12 -> 0 | F12: =C12-E12 -> 0
A13: =IF('Ingresos - Gastos'!A26="","",'Ingresos - Gastos'!A26) | B13: ='Ingresos - Gastos'!D26/12 -> 0 | C13: ='Ingresos - Gastos'!D26 -> 0 | D13: =B13 -> 0 | E13: =D13*12 -> 0 | F13: =C13-E13 -> 0
A14: Seguros | B14: =SUM(B15:B18) -> 120 | C14: =SUM(C15:C18) -> 1440 | D14: =SUM(D15:D18) -> 120 | E14: =SUM(E15:E18) -> 1440 | F14: =SUM(F15:F18) -> 0
A15: =IF('Ingresos - Gastos'!A28="","",'Ingresos - Gastos'!A28) -> Seguro de vida | B15: ='Ingresos - Gastos'!D28/12 -> 30 | C15: ='Ingresos - Gastos'!D28 -> 360 | D15: =B15 -> 30 | E15: =D15*12 -> 360 | F15: =C15-E15 -> 0
A16: =IF('Ingresos - Gastos'!A29="","",'Ingresos - Gastos'!A29) -> Seguro de salud | B16: ='Ingresos - Gastos'!D29/12 -> 90 | C16: ='Ingresos - Gastos'!D29 -> 1080 | D16: =B16 -> 90 | E16: =D16*12 -> 1080 | F16: =C16-E16 -> 0
A17: =IF('Ingresos - Gastos'!A30="","",'Ingresos - Gastos'!A30) | B17: ='Ingresos - Gastos'!D30/12 -> 0 | C17: ='Ingresos - Gastos'!D30 -> 0 | D17: =B17 -> 0 | E17: =D17*12 -> 0 | F17: =C17-E17 -> 0
A18: =IF('Ingresos - Gastos'!A31="","",'Ingresos - Gastos'!A31) | B18: ='Ingresos - Gastos'!D31/12 -> 0 | C18: ='Ingresos - Gastos'!D31 -> 0 | D18: =B18 -> 0 | E18: =D18*12 -> 0 | F18: =C18-E18 -> 0
A19: Ahorro / Inversión | B19: =SUM(B20:B22) -> 150 | C19: =SUM(C20:C22) -> 1800 | D19: =SUM(D20:D22) -> 150 | E19: =SUM(E20:E22) -> 1800 | F19: =SUM(F20:F22) -> 0
A20: =IF('Ingresos - Gastos'!A33="","",'Ingresos - Gastos'!A33) -> Jubilación (plan de pensiones) | B20: ='Ingresos - Gastos'!D33/12 -> 150 | C20: ='Ingresos - Gastos'!D33 -> 1800 | D20: =B20 -> 150 | E20: =D20*12 -> 1800 | F20: =C20-E20 -> 0
A21: =IF('Ingresos - Gastos'!A34="","",'Ingresos - Gastos'!A34) | B21: ='Ingresos - Gastos'!D34/12 -> 0 | C21: ='Ingresos - Gastos'!D34 -> 0 | D21: =B21 -> 0 | E21: =D21*12 -> 0 | F21: =C21-E21 -> 0
A22: =IF('Ingresos - Gastos'!A35="","",'Ingresos - Gastos'!A35) | B22: ='Ingresos - Gastos'!D35/12 -> 0 | C22: ='Ingresos - Gastos'!D35 -> 0 | D22: =B22 -> 0 | E22: =D22*12 -> 0 | F22: =C22-E22 -> 0
A24: NECESARIOS | B24: =B25+B33+B38+B44+B51 -> 1549.1667 | C24: =C25+C33+C38+C44+C51 -> 18590 | D24: =D25+D33+D38+D44+D51 -> 1549.1667 | E24: =E25+E33+E38+E44+E51 -> 18590 | F24: =F25+F33+F38+F44+F51 -> 0 | G24: =IFERROR(E24/$E$83,0) -> 0.47890154
A25: Recibos y servicios del hogar | B25: =SUM(B26:B32) -> 175.83333 | C25: =SUM(C26:C32) -> 2110 | D25: =SUM(D26:D32) -> 175.83333 | E25: =SUM(E26:E32) -> 2110 | F25: =SUM(F26:F32) -> 0
A26: =IF('Ingresos - Gastos'!A39="","",'Ingresos - Gastos'!A39) -> Agua | B26: ='Ingresos - Gastos'!D39/12 -> 20 | C26: ='Ingresos - Gastos'!D39 -> 240 | D26: =B26 -> 20 | E26: =D26*12 -> 240 | F26: =C26-E26 -> 0
A27: =IF('Ingresos - Gastos'!A40="","",'Ingresos - Gastos'!A40) -> Luz | B27: ='Ingresos - Gastos'!D40/12 -> 55 | C27: ='Ingresos - Gastos'!D40 -> 660 | D27: =B27 -> 55 | E27: =D27*12 -> 660 | F27: =C27-E27 -> 0
A28: =IF('Ingresos - Gastos'!A41="","",'Ingresos - Gastos'!A41) -> Gas / calefacción | B28: ='Ingresos - Gastos'!D41/12 -> 35 | C28: ='Ingresos - Gastos'!D41 -> 420 | D28: =B28 -> 35 | E28: =D28*12 -> 420 | F28: =C28-E28 -> 0
A29: =IF('Ingresos - Gastos'!A42="","",'Ingresos - Gastos'!A42) -> Teléfono / Internet | B29: ='Ingresos - Gastos'!D42/12 -> 45 | C29: ='Ingresos - Gastos'!D42 -> 540 | D29: =B29 -> 45 | E29: =D29*12 -> 540 | F29: =C29-E29 -> 0
A30: =IF('Ingresos - Gastos'!A43="","",'Ingresos - Gastos'!A43) -> Mantenimiento del hogar | B30: ='Ingresos - Gastos'!D43/12 -> 20.833333 | C30: ='Ingresos - Gastos'!D43 -> 250 | D30: =B30 -> 20.833333 | E30: =D30*12 -> 250 | F30: =C30-E30 -> 0
A31: =IF('Ingresos - Gastos'!A44="","",'Ingresos - Gastos'!A44) | B31: ='Ingresos - Gastos'!D44/12 -> 0 | C31: ='Ingresos - Gastos'!D44 -> 0 | D31: =B31 -> 0 | E31: =D31*12 -> 0 | F31: =C31-E31 -> 0
A32: =IF('Ingresos - Gastos'!A45="","",'Ingresos - Gastos'!A45) | B32: ='Ingresos - Gastos'!D45/12 -> 0 | C32: ='Ingresos - Gastos'!D45 -> 0 | D32: =B32 -> 0 | E32: =D32*12 -> 0 | F32: =C32-E32 -> 0
A33: Alimentación | B33: =SUM(B34:B37) -> 580 | C33: =SUM(C34:C37) -> 6960 | D33: =SUM(D34:D37) -> 580 | E33: =SUM(E34:E37) -> 6960 | F33: =SUM(F34:F37) -> 0
A34: =IF('Ingresos - Gastos'!A47="","",'Ingresos - Gastos'!A47) -> Supermercado | B34: ='Ingresos - Gastos'!D47/12 -> 520 | C34: ='Ingresos - Gastos'!D47 -> 6240 | D34: =B34 -> 520 | E34: =D34*12 -> 6240 | F34: =C34-E34 -> 0
A35: =IF('Ingresos - Gastos'!A48="","",'Ingresos - Gastos'!A48) -> Fruterías / mercado | B35: ='Ingresos - Gastos'!D48/12 -> 60 | C35: ='Ingresos - Gastos'!D48 -> 720 | D35: =B35 -> 60 | E35: =D35*12 -> 720 | F35: =C35-E35 -> 0
A36: =IF('Ingresos - Gastos'!A49="","",'Ingresos - Gastos'!A49) | B36: ='Ingresos - Gastos'!D49/12 -> 0 | C36: ='Ingresos - Gastos'!D49 -> 0 | D36: =B36 -> 0 | E36: =D36*12 -> 0 | F36: =C36-E36 -> 0
A37: =IF('Ingresos - Gastos'!A50="","",'Ingresos - Gastos'!A50) | B37: ='Ingresos - Gastos'!D50/12 -> 0 | C37: ='Ingresos - Gastos'!D50 -> 0 | D37: =B37 -> 0 | E37: =D37*12 -> 0 | F37: =C37-E37 -> 0
A38: Cuidado personal / familiar | B38: =SUM(B39:B43) -> 137.5 | C38: =SUM(C39:C43) -> 1650 | D38: =SUM(D39:D43) -> 137.5 | E38: =SUM(E39:E43) -> 1650 | F38: =SUM(F39:F43) -> 0
A39: =IF('Ingresos - Gastos'!A52="","",'Ingresos - Gastos'!A52) -> Ropa y calzado | B39: ='Ingresos - Gastos'!D52/12 -> 91.666667 | C39: ='Ingresos - Gastos'!D52 -> 1100 | D39: =B39 -> 91.666667 | E39: =D39*12 -> 1100 | F39: =C39-E39 -> 0
A40: =IF('Ingresos - Gastos'!A53="","",'Ingresos - Gastos'!A53) -> Farmacia / médicos | B40: ='Ingresos - Gastos'!D53/12 -> 20.833333 | C40: ='Ingresos - Gastos'!D53 -> 250 | D40: =B40 -> 20.833333 | E40: =D40*12 -> 250 | F40: =C40-E40 -> 0
A41: =IF('Ingresos - Gastos'!A54="","",'Ingresos - Gastos'!A54) -> Peluquería y cosmética | B41: ='Ingresos - Gastos'!D54/12 -> 25 | C41: ='Ingresos - Gastos'!D54 -> 300 | D41: =B41 -> 25 | E41: =D41*12 -> 300 | F41: =C41-E41 -> 0
A42: =IF('Ingresos - Gastos'!A55="","",'Ingresos - Gastos'!A55) | B42: ='Ingresos - Gastos'!D55/12 -> 0 | C42: ='Ingresos - Gastos'!D55 -> 0 | D42: =B42 -> 0 | E42: =D42*12 -> 0 | F42: =C42-E42 -> 0
...

Sheet Gráficos
A1: Bloque | B1: Anual
A2: INDISPENSABLES | B2: ='Ingresos - Gastos'!D18 -> 13960
A3: NECESARIOS | B3: ='Ingresos - Gastos'!D37 -> 18590
A4: REVISABLES | B4: ='Ingresos - Gastos'!D73 -> 6268
A7: Ingresos | B7: Anual
A8: Laborales | B8: ='Ingresos - Gastos'!D5 -> 49680
A9: Inversiones | B9: ='Ingresos - Gastos'!D11 -> 300

Sheet Fondo de emergencia
A1: FONDO DE EMERGENCIA
A2: Cuánto aguantáis sin ingresos. La clave: en una emergencia NO se gasta lo mismo — los revisables se cortan el primer día.
A3: A) ¿CUÁNTO CUESTA VIVIR EN MODO EMERGENCIA?
A4: Gasto actual completo | C4: ='Ingresos - Gastos'!D96/12 -> 3234.8333 | E4: Todo lo de la hoja de gastos
A5: − Revisables (se cortan el primer día) | C5: =-'Ingresos - Gastos'!D73/12 -> -522.33333 | E5: Suscripciones, ocio, vacaciones, restaurantes, imprevistos, compras online
A6: − Plan de pensiones | C6: =-'Ingresos - Gastos'!D33/12 -> -150 | E6: Se puede suspender en una emergencia
A7: − Supermercado más ajustado | C7: -80 | E7: EJEMPLO de ajuste — cámbialo o bórralo
A8: − (escribe aquí el concepto) | E8: LIBRE: pon el concepto a la izquierda y en negativo lo que recortarías al mes. Ej.: supermercado −150, ocio −80, ropa −40
A9: − (escribe aquí el concepto)
A10: − (escribe aquí el concepto)
A11: − (escribe aquí el concepto)
A12: GASTO DE SUPERVIVENCIA (al mes) | C12: =SUM(C4:C11) -> 2482.5 | E12: Es la cifra que manda en todo lo de abajo
A14: B) INGRESOS DISPONIBLES
A15: Neto mensual Ana | C15: ='Ingresos - Gastos'!B6 -> 2100 | E15: Solo la nómina: lo que se paga en especie y los extras variables se pierden con el empleo
A16: Neto mensual Luis | C16: ='Ingresos - Gastos'!B7 -> 1850 | E16: Mismo criterio
A17: Paro neto estimado Ana | C17: 1150 | E17: EJEMPLO. Calcula el tuyo en la web del SEPE: depende de tu base de cotización, tiene un tope que sube con los hijos a cargo y baja a partir del día 181
A18: Paro neto estimado Luis | C18: 1050 | E18: EJEMPLO. Mismo criterio. La DURACIÓN se pone en el bloque G
A20: C) ESCENARIOS
A21: Escenario | B21: Ingresos/mes | C21: Déficit/mes | D21: Meses con el colchón | E21: Meses con toda la liquidez
A22: Ana en paro, Luis trabaja | B22: =C16+C17 -> 3000 | C22: =MAX(0,$C$12-B22) -> 0 | D22: =IF(C22>0,$C$33/C22,0) -> 0 | E22: =IF(C22>0,$C$37/C22,0) -> 0
A23: Luis en paro, Ana trabaja | B23: =C15+C18 -> 3150 | C23: =MAX(0,$C$12-B23) -> 0 | D23: =IF(C23>0,$C$33/C23,0) -> 0 | E23: =IF(C23>0,$C$37/C23,0) -> 0
A24: Los dos en paro (cobrando prestación) | B24: =C17+C18 -> 2200 | C24: =MAX(0,$C$12-B24) -> 282.5 | D24: =IF(C24>0,$C$33/C24,0) -> 49.557522 | E24: =IF(C24>0,$C$37/C24,0) -> 75.044248
A25: Los dos en paro, PRESTACIÓN AGOTADA | B25: 0 | C25: =MAX(0,$C$12-B25) -> 2482.5 | D25: =IF(C25>0,$C$33/C25,0) -> 5.6394763 | E25: =IF(C25>0,$C$37/C25,0) -> 8.5397784
A26: Un 0 en «meses» significa que NO hay déficit: ese sueldo cubre el gasto de supervivencia sin tocar el colchón. La última fila es el escenario a vigilar: cuando se acaba la prestación.
A28: D) LIQUIDEZ DISPONIBLE
A29: Colchón de emergencia | C29: ='Patrimonio Neto'!E9 -> 14000 | E29: Intocable, designado para esto
A30: Cuenta corriente común | C30: ='Patrimonio Neto'!E8 -> 4500 | E30: Buffer operativo + lo pendiente de invertir
A31: Cuentas personales | C31: ='Patrimonio Neto'!E10+'Patrimonio Neto'!E11 -> 2700
A33: COLCHÓN DESIGNADO | C33: =C29 -> 14000 | E33: El que se usa en la columna «meses con el colchón»
A37: LIQUIDEZ TOTAL | C37: =C29+C30+C31 -> 21200 | E37: Todo el dinero disponible sin vender inversiones. NO incluye las carteras de inversión ni el plan de pensiones: vender inversiones en mitad de una crisis es justo lo que el colchón evita
A39: E) OBJETIVO DEL FONDO — elige tú el nivel
A40: Escenario | B40: Déficit/mes | C40: Cubrir 6 meses | D40: Cubrir 12 meses | E40: Sobra/falta frente al colchón (12 m)
A41: Ana en paro, Luis trabaja | B41: =C22 -> 0 | C41: =C22*6 -> 0 | D41: =C22*12 -> 0 | E41: =$C$33-D41 -> 14000
A42: Luis en paro, Ana trabaja | B42: =C23 -> 0 | C42: =C23*6 -> 0 | D42: =C23*12 -> 0 | E42: =$C$33-D42 -> 14000
A43: Los dos en paro (cobrando prestación) | B43: =C24 -> 282.5 | C43: =C24*6 -> 1695 | D43: =C24*12 -> 3390 | E43: =$C$33-D43 -> 10610
A44: Los dos en paro, PRESTACIÓN AGOTADA | B44: =C25 -> 2482.5 | C44: =C25*6 -> 14895 | D44: =C25*12 -> 29790 | E44: =$C$33-D44 -> -15790
A45: MEDIA de 3 casos (los de déficit 0 cuentan como uno) | B45: =(MAX(C22,C23)+C24+C25)/3 -> 921.66667 | C45: =B45*6 -> 5530 | D45: =B45*12 -> 11060 | E45: =$C$33-D45 -> 2940
A46: «Ana en paro» y «Luis en paro» son el MISMO suceso (cae uno de los dos), así que cuentan como un solo caso, con el peor de los dos (MAX). Aun así la media da el mismo peso a «cae uno» que a «caen los dos y se agota la prestación», que es mucho menos probable. Úsala como referencia alta, no como objetivo.
A48: F) LO QUE EL COLCHÓN CUBRE ADEMÁS DEL PARO
A49: Desfase hasta el primer cobro del paro | C49: =C4*2 -> 6469.6667 | E49: 2 meses de gasto COMPLETO (no de supervivencia): no cobras el día 1, hay que solicitarlo y el primer pago tarda semanas. Cambia el 2 si quieres otro margen
...

Sheet Panel
A1: PANEL DE MANDO
A2: Toca SOLO las celdas verdes de esta pestaña. Todo lo demás del libro se recalcula. Las pestañas «Objetivos» y «Proyección» son el detalle: no hace falta abrirlas para jugar.
A4: =Proyección!A3 -> ✓ Todos los objetivos se pagan
A5: =IF(LEFT(Proyección!A3,1)="✓","Con estos números tu plan se sostiene.","Sube la aportación de la cartera que salga en rojo abajo, o retrasa/abarata ese objetivo.") -> Con estos números tu plan se sostiene.
A7: TUS CARTERAS — lo que aportas a cada una
A8: CARTERA | B8: RENTABILIDAD | C8: APORTAS €/mes | D8: NECESITA €/mes | E8: DIFERENCIA | F8: ESTADO
A9: Cartera conservadora | B9: 0.035 | C9: 380 | D9: =Objetivos!F19 -> 374.13262 | E9: =C9-D9 -> 5.8673832 | F9: =Objetivos!G19 -> ✓ cubierta
A10: Cartera indexada global | B10: 0.06 | C10: 410 | D10: =Objetivos!F20 -> 404.20673 | E10: =C10-D10 -> 5.7932713 | F10: =Objetivos!G20 -> ✓ cubierta
A11: Plan de pensiones | B11: 0.05 | C11: ='Ingresos - Gastos'!D33/12 -> 150 | D11: =Objetivos!F21 -> 139.06169 | E11: =C11-D11 -> 10.938309 | F11: =Objetivos!G21 -> ✓ cubierta
A12: TOTAL | C12: =SUM(C9:C11) -> 940 | D12: =SUM(D9:D11) -> 917.40104 | E12: =SUM(E9:E11) -> 22.598963
A16: SUPUESTOS
A17: Inflación anual | B17: 0.025 | C17: Cuánto sube el precio de las cosas
A18: Impuestos sobre la plusvalía | B18: 0.22 | C18: Tipo medio al vender (en España la base del ahorro va por tramos, del 19% al 30%)
A19: Incremento anual de la aportación | B19: 0.02 | C19: Si es menor que la inflación, cada año inviertes menos en términos reales
A20: Dejo de aportar dentro de (años) | C20: Vacío = sigue al objetivo de tipo «Jubilación»
A22: CÓMO VAS
A23: Aportas al mes (todas las carteras) | B23: =C12 -> 940
A24: Necesitas al mes | B24: =D12 -> 917.40104 | C24: Suma de lo que pide cada objetivo
A25: → TE FALTA / TE SOBRA | B25: =C12-D12 -> 22.598963 | C25: En negativo, es lo que hay que subir
A26: Tu ahorro real (de tus cuentas) | B26: =Objetivos!B13 -> 930.16667 | C26: Lo que de verdad te sobra cada mes
A27: % de tu ahorro que estás invirtiendo | B27: =Objetivos!B15 -> 0.84931016 | C27: Sin el plan de pensiones
A28: Dejas de aportar en | B28: =Objetivos!B12 -> 2058 | C28: El año de tu jubilación
A29: Patrimonio neto al jubilarte | B29: =IFERROR(INDEX(Proyección!D:D,MATCH(Objetivos!B12,Proyección!A:A,0)),0) -> 873897.37 | C29: Lo que tendrás, ya descontados los impuestos latentes

Sheet Objetivos
A1: OBJETIVOS
A2: Rellena solo las celdas con FONDO VERDE. Importes en euros de HOY y fechas en año real. Cada objetivo va asignado a una CARTERA, y cada cartera compone a su propio ritmo: el dinero a 5 años no puede ir donde el de 30.
A4: PARÁMETROS
A5: Año de partida | B5: =YEAR('Patrimonio Neto'!E1) -> 2026 | C5: Sale de la fecha de «Patrimonio Neto». Es el año 0: los plazos se cuentan desde aquí
A6: Inflación anual | B6: =Panel!B17 -> 0.025 | C6: Se toca en la pestaña «Panel»
A7: Impuestos sobre la plusvalía | B7: =Panel!B18 -> 0.22 | C7: Se toca en la pestaña «Panel»
A8: Rentabilidad MÍNIMA para no perder | B8: =B6/(1-B7) -> 0.032051282 | C8: Inflación ÷ (1 − impuestos). Es el SUELO: por debajo pierdes poder adquisitivo
A9: Incremento anual de la aportación | B9: =Panel!B19 -> 0.02 | C9: Se toca en la pestaña «Panel»
A10: Dejo de aportar dentro de (años) | B10: =IF(Panel!B20="","",Panel!B20) | C10: Se toca en la pestaña «Panel»
A11: → Plazo que se aplica (años) | B11: =IF(B10="",IF(MIN(N26:N45)=9999,999,MIN(N26:N45)),B10) -> 32 | C11: El que usa la proyección
A12: → …es decir, el año | B12: =B5+B11 -> 2058 | C12: El año en que dejas de aportar
A13: Tu ahorro real (de «Ingresos - Gastos») | B13: ='Ingresos - Gastos'!D99 -> 930.16667 | C13: Lo que de verdad te sobra cada mes según tus cuentas
A14: → Aportas al mes (todas las carteras) | B14: =SUM(E19:E21) -> 940 | C14: Suma de la columna «aportación mensual»
A15: → % de tu ahorro que inviertes | B15: =IF(B13=0,0,(B14-E21)/B13) -> 0.84931016 | C15: Sin el plan de pensiones, que ya está contado como gasto
A17: TUS CARTERAS (cada una compone a su ritmo)
A18: CARTERA | B18: RENTABILIDAD | C18: YA INVERTIDO (€) | D18: APORTAS AL EMPEZAR (€) | E18: APORTACIÓN MENSUAL (€) | F18: → NECESARIO AL MES (€) | G18: ESTADO | H18: NOTAS
A19: Cartera conservadora | B19: =Panel!B9 -> 0.035 | C19: ='Patrimonio Neto'!E12 -> 3000 | D19: 0 | E19: =Panel!C9 -> 380 | F19: =SUMIFS($L$26:$L$45,$B$26:$B$45,$A19) -> 374.13262 | G19: =IF(F19=0,"— sin objetivos",IF(E19>=F19,"✓ cubierta","⚠ faltan "&TEXT(F19-E19,"#,##0")&" €/mes")) -> ✓ cubierta | H19: EJEMPLO. Mezcla con poca renta variable, para objetivos a menos de ~10 años. La rentabilidad es un SUPUESTO para jugar, no una promesa: pon la de tu producto
A20: Cartera indexada global | B20: =Panel!B10 -> 0.06 | C20: ='Patrimonio Neto'!E13 -> 18000 | D20: 0 | E20: =Panel!C10 -> 410 | F20: =SUMIFS($L$26:$L$45,$B$26:$B$45,$A20) -> 404.20673 | G20: =IF(F20=0,"— sin objetivos",IF(E20>=F20,"✓ cubierta","⚠ faltan "&TEXT(F20-E20,"#,##0")&" €/mes")) -> ✓ cubierta | H20: EJEMPLO. 100% renta variable global indexada, para objetivos a 15+ años. Puede caer un 20-30% en un mal año: por eso no se usa para lo cercano. La rentabilidad es un SUPUESTO
A21: Plan de pensiones | B21: =Panel!B11 -> 0.05 | C21: ='Patrimonio Neto'!E14 -> 9000 | D21: 0 | E21: =Panel!C11 -> 150 | F21: =SUMIFS($L$26:$L$45,$B$26:$B$45,$A21) -> 139.06169 | G21: =IF(F21=0,"— sin objetivos",IF(E21>=F21,"✓ cubierta","⚠ faltan "&TEXT(F21-E21,"#,##0")&" €/mes")) -> ✓ cubierta | H21: EJEMPLO. La aportación mensual sale sola de «Ingresos - Gastos» (fila del plan de pensiones). La rentabilidad es un SUPUESTO
A22: TOTAL | C22: =SUM(C19:C21) -> 30000 | D22: =SUM(D19:D21) -> 0 | E22: =SUM(E19:E21) -> 940 | F22: =SUM(F19:F21) -> 917.40104
A24: TUS OBJETIVOS
A25: OBJETIVO | B25: CARTERA | C25: TIPO | D25: AÑO | E25: DENTRO DE | F25: IMPORTE HOY (€) | G25: RENTA MENSUAL HOY (€) | H25: AÑOS DE CONSUMO | I25: TOTAL A RETIRAR (€ de su año) | J25: CAPITAL NECESARIO AL LLEGAR (€) | K25: SI LO PAGAS HOY DE GOLPE (€) | L25: APORTACIÓN MENSUAL NECESARIA (€) | M25: NOTAS | N25: aux: jubilación
A26: Cambio de coche | B26: Cartera conservadora | C26: Único | D26: 2032 | E26: =IF($C26="",0,D26-$B$5) -> 6 | F26: 12000 | I26: =IF($C26="","",IF(OR($C26="Renta",$C26="Jubilación"),G26*12*(1+$B$6)^E26*((1+$B$6)^H26-1)/$B$6,F26*(1+$B$6)^E26)) -> 13916.321 | J26: =IF($C26="","",IF(OR($C26="Renta",$C26="Jubilación"),G26*12*(1+$B$6)^E26*IF(ABS($B$6-IFERROR(VLOOKUP($B26,$A$19:$B$21,2,FALSE),$B$8))<0.0000001,H26,(1-((1+$B$6)/(1+IFERROR(VLOOKUP($B26,$A$19:$B$21,2,FALSE),$B$8)))^H26)/(1-(1+$B$6)/(1+IFERROR(VLOOKUP($B26,$A$19:$B$21,2,FALSE),$B$8)))),I26)) -> 13916.321 | K26: =IF($C26="","",J26/(1+IFERROR(VLOOKUP($B26,$A$19:$B$21,2,FALSE),$B$8))^E26) -> 11320.936 | L26: =IF($C26="","",IF(E26<=0,"",((J26*IFERROR(VLOOKUP($B26,$A$19:$B$21,2,FALSE),$B$8))/((1+IFERROR(VLOOKUP($B26,$A$19:$B$21,2,FALSE),$B$8))^E26-1))/12)) -> 177.04832 | M26: A 5 años no conviene tenerlo en 100% renta variable: una caída justo antes te obliga a vender en pérdidas | N26: =IF($C26="Jubilación",E26,9999) -> 9999
A27: Cambio de coche | B27: Cartera conservadora | C27: Único | D27: 2042 | E27: =IF($C27="",0,D27-$B$5) -> 16 | F27: 12000 | I27: =IF($C27="","",IF(OR($C27="Renta",$C27="Jubilación"),G27*12*(1+$B$6)^E27*((1+$B$6)^H27-1)/$B$6,F27*(1+$B$6)^E27)) -> 17814.067 | J27: =IF($C27="","",IF(OR($C27="Renta",$C27="Jubilación"),G27*12*(1+$B$6)^E27*IF(ABS($B$6-IFERROR(VLOOKUP($B27,$A$19:$B$21,2,FALSE),$B$8))<0.0000001,H27,(1-((1+$B$6)/(1+IFERROR(VLOOKUP($B27,$A$19:$B$21,2,FALSE),$B$8)))^H27)/(1-(1+$B$6)/(1+IFERROR(VLOOKUP($B27,$A$19:$B$21,2,FALSE),$B$8)))),I27)) -> 17814.067 | K27: =IF($C27="","",J27/(1+IFERROR(VLOOKUP($B27,$A$19:$B$21,2,FALSE),$B$8))^E27) -> 10273.478 | L27: =IF($C27="","",IF(E27<=0,"",((J27*IFERROR(VLOOKUP($B27,$A$19:$B$21,2,FALSE),$B$8))/((1+IFERROR(VLOOKUP($B27,$A$19:$B$21,2,FALSE),$B$8))^E27-1))/12)) -> 70.788399 | N27: =IF($C27="Jubilación",E27,9999) -> 9999
A28: Cambio de coche | B28: Cartera conservadora | C28: Único | D28: 2052 | E28: =IF($C28="",0,D28-$B$5) -> 26 | F28: 12000 | I28: =IF($C28="","",IF(OR($C28="Renta",$C28="Jubilación"),G28*12*(1+$B$6)^E28*((1+$B$6)^H28-1)/$B$6,F28*(1+$B$6)^E28)) -> 22803.512 | J28: =IF($C28="","",IF(OR($C28="Renta",$C28="Jubilación"),G28*12*(1+$B$6)^E28*IF(ABS($B$6-IFERROR(VLOOKUP($B28,$A$19:$B$21,2,FALSE),$B$8))<0.0000001,H28,(1-((1+$B$6)/(1+IFERROR(VLOOKUP($B28,$A$19:$B$21,2,FALSE),$B$8)))^H28)/(1-(1+$B$6)/(1+IFERROR(VLOOKUP($B28,$A$19:$B$21,2,FALSE),$B$8)))),I28)) -> 22803.512 | K28: =IF($C28="","",J28/(1+IFERROR(VLOOKUP($B28,$A$19:$B$21,2,FALSE),$B$8))^E28) -> 9322.9349 | L28: =IF($C28="","",IF(E28<=0,"",((J28*IFERROR(VLOOKUP($B28,$A$19:$B$21,2,FALSE),$B$8))/((1+IFERROR(VLOOKUP($B28,$A$19:$B$21,2,FALSE),$B$8))^E28-1))/12)) -> 45.997338 | N28: =IF($C28="Jubilación",E28,9999) -> 9999
A29: Reforma de la cocina | B29: Cartera conservadora | C29: Único | D29: 2035 | E29: =IF($C29="",0,D29-$B$5) -> 9 | F29: 8000 | I29: =IF($C29="","",IF(OR($C29="Renta",$C29="Jubilación"),G29*12*(1+$B$6)^E29*((1+$B$6)^H29-1)/$B$6,F29*(1+$B$6)^E29)) -> 9990.9038 | J29: =IF($C29="","",IF(OR($C29="Renta",$C29="Jubilación"),G29*12*(1+$B$6)^E29*IF(ABS($B$6-IFERROR(VLOOKUP($B29,$A$19:$B$21,2,FALSE),$B$8))<0.0000001,H29,(1-((1+$B$6)/(1+IFERROR(VLOOKUP($B29,$A$19:$B$21,2,FALSE),$B$8)))^H29)/(1-(1+$B$6)/(1+IFERROR(VLOOKUP($B29,$A$19:$B$21,2,FALSE),$B$8)))),I29)) -> 9990.9038 | K29: =IF($C29="","",J29/(1+IFERROR(VLOOKUP($B29,$A$19:$B$21,2,FALSE),$B$8))^E29) -> 7330.6355 | L29: =IF($C29="","",IF(E29<=0,"",((J29*IFERROR(VLOOKUP($B29,$A$19:$B$21,2,FALSE),$B$8))/((1+IFERROR(VLOOKUP($B29,$A$19:$B$21,2,FALSE),$B$8))^E29-1))/12)) -> 80.298563 | N29: =IF($C29="Jubilación",E29,9999) -> 9999
A30: Universidad Leo — 1.º | B30: Cartera indexada global | C30: Único | D30: 2041 | E30: =IF($C30="",0,D30-$B$5) -> 15 | F30: 6000 | I30: =IF($C30="","",IF(OR($C30="Renta",$C30="Jubilación"),G30*12*(1+$B$6)^E30*((1+$B$6)^H30-1)/$B$6,F30*(1+$B$6)^E30)) -> 8689.789 | J30: =IF($C30="","",IF(OR($C30="Renta",$C30="Jubilación"),G30*12*(1+$B$6)^E30*IF(ABS($B$6-IFERROR(VLOOKUP($B30,$A$19:$B$21,2,FALSE),$B$8))<0.0000001,H30,(1-((1+$B$6)/(1+IFERROR(VLOOKUP($B30,$A$19:$B$21,2,FALSE),$B$8)))^H30)/(1-(1+$B$6)/(1+IFERROR(VLOOKUP($B30,$A$19:$B$21,2,FALSE),$B$8)))),I30)) -> 8689.789 | K30: =IF($C30="","",J30/(1+IFERROR(VLOOKUP($B30,$A$19:$B$21,2,FALSE),$B$8))^E30) -> 3625.9453 | L30: =IF($C30="","",IF(E30<=0,"",((J30*IFERROR(VLOOKUP($B30,$A$19:$B$21,2,FALSE),$B$8))/((1+IFERROR(VLOOKUP($B30,$A$19:$B$21,2,FALSE),$B$8))^E30-1))/12)) -> 31.111446 | M30: Faltan 15 años: puede ir en la indexada. Cuando falten ~5, conviene pasarlo a la conservadora | N30: =IF($C30="Jubilación",E30,9999) -> 9999
A31: Universidad Leo — 2.º | B31: Cartera indexada global | C31: Único | D31: 2042 | E31: =IF($C31="",0,D31-$B$5) -> 16 | F31: 6000 | I31: =IF($C31="","",IF(OR($C31="Renta",$C31="Jubilación"),G31*12*(1+$B$6)^E31*((1+$B$6)^H31-1)/$B$6,F31*(1+$B$6)^E31)) -> 8907.0337 | J31: =IF($C31="","",IF(OR($C31="Renta",$C31="Jubilación"),G31*12*(1+$B$6)^E31*IF(ABS($B$6-IFERROR(VLOOKUP($B31,$A$19:$B$21,2,FALSE),$B$8))<0.0000001,H31,(1-((1+$B$6)/(1+IFERROR(VLOOKUP($B31,$A$19:$B$21,2,FALSE),$B$8)))^H31)/(1-(1+$B$6)/(1+IFERROR(VLOOKUP($B31,$A$19:$B$21,2,FALSE),$B$8)))),I31)) -> 8907.0337 | K31: =IF($C31="","",J31/(1+IFERROR(VLOOKUP($B31,$A$19:$B$21,2,FALSE),$B$8))^E31) -> 3506.2207 | L31: =IF($C31="","",IF(E31<=0,"",((J31*IFERROR(VLOOKUP($B31,$A$19:$B$21,2,FALSE),$B$8))/((1+IFERROR(VLOOKUP($B31,$A$19:$B$21,2,FALSE),$B$8))^E31-1))/12)) -> 28.912338 | N31: =IF($C31="Jubilación",E31,9999) -> 9999
A32: Universidad Leo — 3.º | B32: Cartera indexada global | C32: Único | D32: 2043 | E32: =IF($C32="",0,D32-$B$5) -> 17 | F32: 6000 | I32: =IF($C32="","",IF(OR($C32="Renta",$C32="Jubilación"),G32*12*(1+$B$6)^E32*((1+$B$6)^H32-1)/$B$6,F32*(1+$B$6)^E32)) -> 9129.7096 | J32: =IF($C32="","",IF(OR($C32="Renta",$C32="Jubilación"),G32*12*(1+$B$6)^E32*IF(ABS($B$6-IFERROR(VLOOKUP($B32,$A$19:$B$21,2,FALSE),$B$8))<0.0000001,H32,(1-((1+$B$6)/(1+IFERROR(VLOOKUP($B32,$A$19:$B$21,2,FALSE),$B$8)))^H32)/(1-(1+$B$6)/(1+IFERROR(VLOOKUP($B32,$A$19:$B$21,2,FALSE),$B$8)))),I32)) -> 9129.7096 | K32: =IF($C32="","",J32/(1+IFERROR(VLOOKUP($B32,$A$19:$B$21,2,FALSE),$B$8))^E32) -> 3390.4493 | L32: =IF($C32="","",IF(E32<=0,"",((J32*IFERROR(VLOOKUP($B32,$A$19:$B$21,2,FALSE),$B$8))/((1+IFERROR(VLOOKUP($B32,$A$19:$B$21,2,FALSE),$B$8))^E32-1))/12)) -> 26.966731 | N32: =IF($C32="Jubilación",E32,9999) -> 9999
A33: Universidad Leo — 4.º | B33: Cartera indexada global | C33: Único | D33: 2044 | E33: =IF($C33="",0,D33-$B$5) -> 18 | F33: 6000 | I33: =IF($C33="","",IF(OR($C33="Renta",$C33="Jubilación"),G33*12*(1+$B$6)^E33*((1+$B$6)^H33-1)/$B$6,F33*(1+$B$6)^E33)) -> 9357.9523 | J33: =IF($C33="","",IF(OR($C33="Renta",$C33="Jubilación"),G33*12*(1+$B$6)^E33*IF(ABS($B$6-IFERROR(VLOOKUP($B33,$A$19:$B$21,2,FALSE),$B$8))<0.0000001,H33,(1-((1+$B$6)/(1+IFERROR(VLOOKUP($B33,$A$19:$B$21,2,FALSE),$B$8)))^H33)/(1-(1+$B$6)/(1+IFERROR(VLOOKUP($B33,$A$19:$B$21,2,FALSE),$B$8)))),I33)) -> 9357.9523 | K33: =IF($C33="","",J33/(1+IFERROR(VLOOKUP($B33,$A$19:$B$21,2,FALSE),$B$8))^E33) -> 3278.5005 | L33: =IF($C33="","",IF(E33<=0,"",((J33*IFERROR(VLOOKUP($B33,$A$19:$B$21,2,FALSE),$B$8))/((1+IFERROR(VLOOKUP($B33,$A$19:$B$21,2,FALSE),$B$8))^E33-1))/12)) -> 25.23258 | N33: =IF($C33="Jubilación",E33,9999) -> 9999
A34: Jubilación | B34: Cartera indexada global | C34: Jubilación | D34: 2058 | E34: =IF($C34="",0,D34-$B$5) -> 32 | G34: 700 | H34: 25 | I34: =IF($C34="","",IF(OR($C34="Renta",$C34="Jubilación"),G34*12*(1+$B$6)^E34*((1+$B$6)^H34-1)/$B$6,F34*(1+$B$6)^E34)) -> 632313.44 | J34: =IF($C34="","",IF(OR($C34="Renta",$C34="Jubilación"),G34*12*(1+$B$6)^E34*IF(ABS($B$6-IFERROR(VLOOKUP($B34,$A$19:$B$21,2,FALSE),$B$8))<0.0000001,H34,(1-((1+$B$6)/(1+IFERROR(VLOOKUP($B34,$A$19:$B$21,2,FALSE),$B$8)))^H34)/(1-(1+$B$6)/(1+IFERROR(VLOOKUP($B34,$A$19:$B$21,2,FALSE),$B$8)))),I34)) -> 318459.93 | K34: =IF($C34="","",J34/(1+IFERROR(VLOOKUP($B34,$A$19:$B$21,2,FALSE),$B$8))^E34) -> 49347.722 | L34: =IF($C34="","",IF(E34<=0,"",((J34*IFERROR(VLOOKUP($B34,$A$19:$B$21,2,FALSE),$B$8))/((1+IFERROR(VLOOKUP($B34,$A$19:$B$21,2,FALSE),$B$8))^E34-1))/12)) -> 291.98363 | M34: COMPLEMENTO a la pensión pública, no el total. El tipo «Jubilación» marca además el año en que dejas de aportar | N34: =IF($C34="Jubilación",E34,9999) -> 32
A35: Jubilación — parte del plan de pensiones | B35: Plan de pensiones | C35: Jubilación | D35: 2058 | E35: =IF($C35="",0,D35-$B$5) -> 32 | G35: 250 | H35: 25 | I35: =IF($C35="","",IF(OR($C35="Renta",$C35="Jubilación"),G35*12*(1+$B$6)^E35*((1+$B$6)^H35-1)/$B$6,F35*(1+$B$6)^E35)) -> 225826.23 | J35: =IF($C35="","",IF(OR($C35="Renta",$C35="Jubilación"),G35*12*(1+$B$6)^E35*IF(ABS($B$6-IFERROR(VLOOKUP($B35,$A$19:$B$21,2,FALSE),$B$8))<0.0000001,H35,(1-((1+$B$6)/(1+IFERROR(VLOOKUP($B35,$A$19:$B$21,2,FALSE),$B$8)))^H35)/(1-(1+$B$6)/(1+IFERROR(VLOOKUP($B35,$A$19:$B$21,2,FALSE),$B$8)))),I35)) -> 125654.19 | K35: =IF($C35="","",J35/(1+IFERROR(VLOOKUP($B35,$A$19:$B$21,2,FALSE),$B$8))^E35) -> 26370.563 | L35: =IF($C35="","",IF(E35<=0,"",((J35*IFERROR(VLOOKUP($B35,$A$19:$B$21,2,FALSE),$B$8))/((1+IFERROR(VLOOKUP($B35,$A$19:$B$21,2,FALSE),$B$8))^E35-1))/12)) -> 139.06169 | M35: La otra parte del complemento, pagada desde el plan de pensiones | N35: =IF($C35="Jubilación",E35,9999) -> 32
E36: =IF($C36="",0,D36-$B$5) -> 0 | I36: =IF($C36="","",IF(OR($C36="Renta",$C36="Jubilación"),G36*12*(1+$B$6)^E36*((1+$B$6)^H36-1)/$B$6,F36*(1+$B$6)^E36)) | J36: =IF($C36="","",IF(OR($C36="Renta",$C36="Jubilación"),G36*12*(1+$B$6)^E36*IF(ABS($B$6-IFERROR(VLOOKUP($B36,$A$19:$B$21,2,FALSE),$B$8))<0.0000001,H36,(1-((1+$B$6)/(1+IFERROR(VLOOKUP($B36,$A$19:$B$21,2,FALSE),$B$8)))^H36)/(1-(1+$B$6)/(1+IFERROR(VLOOKUP($B36,$A$19:$B$21,2,FALSE),$B$8)))),I36)) | K36: =IF($C36="","",J36/(1+IFERROR(VLOOKUP($B36,$A$19:$B$21,2,FALSE),$B$8))^E36) | L36: =IF($C36="","",IF(E36<=0,"",((J36*IFERROR(VLOOKUP($B36,$A$19:$B$21,2,FALSE),$B$8))/((1+IFERROR(VLOOKUP($B36,$A$19:$B$21,2,FALSE),$B$8))^E36-1))/12)) | N36: =IF($C36="Jubilación",E36,9999) -> 9999
E37: =IF($C37="",0,D37-$B$5) -> 0 | I37: =IF($C37="","",IF(OR($C37="Renta",$C37="Jubilación"),G37*12*(1+$B$6)^E37*((1+$B$6)^H37-1)/$B$6,F37*(1+$B$6)^E37)) | J37: =IF($C37="","",IF(OR($C37="Renta",$C37="Jubilación"),G37*12*(1+$B$6)^E37*IF(ABS($B$6-IFERROR(VLOOKUP($B37,$A$19:$B$21,2,FALSE),$B$8))<0.0000001,H37,(1-((1+$B$6)/(1+IFERROR(VLOOKUP($B37,$A$19:$B$21,2,FALSE),$B$8)))^H37)/(1-(1+$B$6)/(1+IFERROR(VLOOKUP($B37,$A$19:$B$21,2,FALSE),$B$8)))),I37)) | K37: =IF($C37="","",J37/(1+IFERROR(VLOOKUP($B37,$A$19:$B$21,2,FALSE),$B$8))^E37) | L37: =IF($C37="","",IF(E37<=0,"",((J37*IFERROR(VLOOKUP($B37,$A$19:$B$21,2,FALSE),$B$8))/((1+IFERROR(VLOOKUP($B37,$A$19:$B$21,2,FALSE),$B$8))^E37-1))/12)) | N37: =IF($C37="Jubilación",E37,9999) -> 9999
E38: =IF($C38="",0,D38-$B$5) -> 0 | I38: =IF($C38="","",IF(OR($C38="Renta",$C38="Jubilación"),G38*12*(1+$B$6)^E38*((1+$B$6)^H38-1)/$B$6,F38*(1+$B$6)^E38)) | J38: =IF($C38="","",IF(OR($C38="Renta",$C38="Jubilación"),G38*12*(1+$B$6)^E38*IF(ABS($B$6-IFERROR(VLOOKUP($B38,$A$19:$B$21,2,FALSE),$B$8))<0.0000001,H38,(1-((1+$B$6)/(1+IFERROR(VLOOKUP($B38,$A$19:$B$21,2,FALSE),$B$8)))^H38)/(1-(1+$B$6)/(1+IFERROR(VLOOKUP($B38,$A$19:$B$21,2,FALSE),$B$8)))),I38)) | K38: =IF($C38="","",J38/(1+IFERROR(VLOOKUP($B38,$A$19:$B$21,2,FALSE),$B$8))^E38) | L38: =IF($C38="","",IF(E38<=0,"",((J38*IFERROR(VLOOKUP($B38,$A$19:$B$21,2,FALSE),$B$8))/((1+IFERROR(VLOOKUP($B38,$A$19:$B$21,2,FALSE),$B$8))^E38-1))/12)) | N38: =IF($C38="Jubilación",E38,9999) -> 9999
E39: =IF($C39="",0,D39-$B$5) -> 0 | I39: =IF($C39="","",IF(OR($C39="Renta",$C39="Jubilación"),G39*12*(1+$B$6)^E39*((1+$B$6)^H39-1)/$B$6,F39*(1+$B$6)^E39)) | J39: =IF($C39="","",IF(OR($C39="Renta",$C39="Jubilación"),G39*12*(1+$B$6)^E39*IF(ABS($B$6-IFERROR(VLOOKUP($B39,$A$19:$B$21,2,FALSE),$B$8))<0.0000001,H39,(1-((1+$B$6)/(1+IFERROR(VLOOKUP($B39,$A$19:$B$21,2,FALSE),$B$8)))^H39)/(1-(1+$B$6)/(1+IFERROR(VLOOKUP($B39,$A$19:$B$21,2,FALSE),$B$8)))),I39)) | K39: =IF($C39="","",J39/(1+IFERROR(VLOOKUP($B39,$A$19:$B$21,2,FALSE),$B$8))^E39) | L39: =IF($C39="","",IF(E39<=0,"",((J39*IFERROR(VLOOKUP($B39,$A$19:$B$21,2,FALSE),$B$8))/((1+IFERROR(VLOOKUP($B39,$A$19:$B$21,2,FALSE),$B$8))^E39-1))/12)) | N39: =IF($C39="Jubilación",E39,9999) -> 9999
E40: =IF($C40="",0,D40-$B$5) -> 0 | I40: =IF($C40="","",IF(OR($C40="Renta",$C40="Jubilación"),G40*12*(1+$B$6)^E40*((1+$B$6)^H40-1)/$B$6,F40*(1+$B$6)^E40)) | J40: =IF($C40="","",IF(OR($C40="Renta",$C40="Jubilación"),G40*12*(1+$B$6)^E40*IF(ABS($B$6-IFERROR(VLOOKUP($B40,$A$19:$B$21,2,FALSE),$B$8))<0.0000001,H40,(1-((1+$B$6)/(1+IFERROR(VLOOKUP($B40,$A$19:$B$21,2,FALSE),$B$8)))^H40)/(1-(1+$B$6)/(1+IFERROR(VLOOKUP($B40,$A$19:$B$21,2,FALSE),$B$8)))),I40)) | K40: =IF($C40="","",J40/(1+IFERROR(VLOOKUP($B40,$A$19:$B$21,2,FALSE),$B$8))^E40) | L40: =IF($C40="","",IF(E40<=0,"",((J40*IFERROR(VLOOKUP($B40,$A$19:$B$21,2,FALSE),$B$8))/((1+IFERROR(VLOOKUP($B40,$A$19:$B$21,2,FALSE),$B$8))^E40-1))/12)) | N40: =IF($C40="Jubilación",E40,9999) -> 9999
E41: =IF($C41="",0,D41-$B$5) -> 0 | I41: =IF($C41="","",IF(OR($C41="Renta",$C41="Jubilación"),G41*12*(1+$B$6)^E41*((1+$B$6)^H41-1)/$B$6,F41*(1+$B$6)^E41)) | J41: =IF($C41="","",IF(OR($C41="Renta",$C41="Jubilación"),G41*12*(1+$B$6)^E41*IF(ABS($B$6-IFERROR(VLOOKUP($B41,$A$19:$B$21,2,FALSE),$B$8))<0.0000001,H41,(1-((1+$B$6)/(1+IFERROR(VLOOKUP($B41,$A$19:$B$21,2,FALSE),$B$8)))^H41)/(1-(1+$B$6)/(1+IFERROR(VLOOKUP($B41,$A$19:$B$21,2,FALSE),$B$8)))),I41)) | K41: =IF($C41="","",J41/(1+IFERROR(VLOOKUP($B41,$A$19:$B$21,2,FALSE),$B$8))^E41) | L41: =IF($C41="","",IF(E41<=0,"",((J41*IFERROR(VLOOKUP($B41,$A$19:$B$21,2,FALSE),$B$8))/((1+IFERROR(VLOOKUP($B41,$A$19:$B$21,2,FALSE),$B$8))^E41-1))/12)) | N41: =IF($C41="Jubilación",E41,9999) -> 9999
E42: =IF($C42="",0,D42-$B$5) -> 0 | I42: =IF($C42="","",IF(OR($C42="Renta",$C42="Jubilación"),G42*12*(1+$B$6)^E42*((1+$B$6)^H42-1)/$B$6,F42*(1+$B$6)^E42)) | J42: =IF($C42="","",IF(OR($C42="Renta",$C42="Jubilación"),G42*12*(1+$B$6)^E42*IF(ABS($B$6-IFERROR(VLOOKUP($B42,$A$19:$B$21,2,FALSE),$B$8))<0.0000001,H42,(1-((1+$B$6)/(1+IFERROR(VLOOKUP($B42,$A$19:$B$21,2,FALSE),$B$8)))^H42)/(1-(1+$B$6)/(1+IFERROR(VLOOKUP($B42,$A$19:$B$21,2,FALSE),$B$8)))),I42)) | K42: =IF($C42="","",J42/(1+IFERROR(VLOOKUP($B42,$A$19:$B$21,2,FALSE),$B$8))^E42) | L42: =IF($C42="","",IF(E42<=0,"",((J42*IFERROR(VLOOKUP($B42,$A$19:$B$21,2,FALSE),$B$8))/((1+IFERROR(VLOOKUP($B42,$A$19:$B$21,2,FALSE),$B$8))^E42-1))/12)) | N42: =IF($C42="Jubilación",E42,9999) -> 9999
E43: =IF($C43="",0,D43-$B$5) -> 0 | I43: =IF($C43="","",IF(OR($C43="Renta",$C43="Jubilación"),G43*12*(1+$B$6)^E43*((1+$B$6)^H43-1)/$B$6,F43*(1+$B$6)^E43)) | J43: =IF($C43="","",IF(OR($C43="Renta",$C43="Jubilación"),G43*12*(1+$B$6)^E43*IF(ABS($B$6-IFERROR(VLOOKUP($B43,$A$19:$B$21,2,FALSE),$B$8))<0.0000001,H43,(1-((1+$B$6)/(1+IFERROR(VLOOKUP($B43,$A$19:$B$21,2,FALSE),$B$8)))^H43)/(1-(1+$B$6)/(1+IFERROR(VLOOKUP($B43,$A$19:$B$21,2,FALSE),$B$8)))),I43)) | K43: =IF($C43="","",J43/(1+IFERROR(VLOOKUP($B43,$A$19:$B$21,2,FALSE),$B$8))^E43) | L43: =IF($C43="","",IF(E43<=0,"",((J43*IFERROR(VLOOKUP($B43,$A$19:$B$21,2,FALSE),$B$8))/((1+IFERROR(VLOOKUP($B43,$A$19:$B$21,2,FALSE),$B$8))^E43-1))/12)) | N43: =IF($C43="Jubilación",E43,9999) -> 9999
...

Sheet Proyección
A1: PROYECCIÓN POR CARTERAS
A2: NO se edita nada aquí. Cada cartera es una bolsa independiente que compone a su propia rentabilidad; los objetivos rescatan de la suya. A la izquierda el total, a la derecha el detalle.
A3: =IF(SUM(L6:L90)+SUM(R6:R90)+SUM(X6:X90)<0.01,"✓ Todos los objetivos se pagan","⚠ NO LLEGAS: el primer objetivo que se queda sin pagar es en "&MIN(SUMPRODUCT(MIN((L6:L90>0.01)*A6:A90+(L6:L90<=0.01)*999999)),SUMPRODUCT(MIN((R6:R90>0.01)*A6:A90+(R6:R90<=0.01)*999999)),SUMPRODUCT(MIN((X6:X90>0.01)*A6:A90+(X6:X90<=0.01)*999999)))) -> ✓ Todos los objetivos se pagan
A4: RESUMEN | G4: Cartera conservadora | M4: Cartera indexada global | S4: Plan de pensiones
A5: AÑO | B5: DENTRO DE | C5: TOTAL ACUMULADO | D5: TOTAL NETO (si vendes) | E5: APORTAS EL AÑO | F5: RETIRAS EL AÑO | G5: APORTAS | H5: VALOR | I5: BASE (lo aportado) | J5: RETIRAS | K5: COSTE REAL (con impuesto) | L5: ⚠ SIN CUBRIR | M5: APORTAS | N5: VALOR | O5: BASE (lo aportado) | P5: RETIRAS | Q5: COSTE REAL (con impuesto) | R5: ⚠ SIN CUBRIR | S5: APORTAS | T5: VALOR | U5: BASE (lo aportado) | V5: RETIRAS | W5: COSTE REAL (con impuesto) | X5: ⚠ SIN CUBRIR
A6: =Objetivos!$B$5+B6 -> 2027 | B6: 1 | C6: =H6+N6+T6 -> 41280 | D6: =(H6-MAX(0,H6-I6)*Objetivos!$B$7)+(N6-MAX(0,N6-O6)*Objetivos!$B$7)+(T6-MAX(0,T6-U6)*Objetivos!$B$7) -> 41280 | E6: =G6+M6+S6 -> 41280 | F6: =J6+P6+V6 -> 0 | G6: =IF(B6>=Objetivos!$B$11,0,IF(B6=1,Objetivos!$E$19*12+Objetivos!$C$19+Objetivos!$D$19,Objetivos!$E$19*12*(1+Objetivos!$B$9)^(B6-1))) -> 7560 | H6: =G6 -> 7560 | I6: =G6 -> 7560 | J6: =MIN(H6,SUMIFS(Objetivos!$I$26:$I$45,Objetivos!$E$26:$E$45,B6,Objetivos!$C$26:$C$45,"Único",Objetivos!$B$26:$B$45,Objetivos!$A$19)+SUMPRODUCT(((Objetivos!$C$26:$C$45="Renta")+(Objetivos!$C$26:$C$45="Jubilación"))*(Objetivos!$B$26:$B$45=Objetivos!$A$19)*(B6>=Objetivos!$E$26:$E$45)*(B6<Objetivos!$E$26:$E$45+Objetivos!$H$26:$H$45)*Objetivos!$G$26:$G$45)*12*(1+Objetivos!$B$6)^B6) -> 0 | K6: =J6+IF(H6=0,0,J6*MAX(0,H6-I6)/H6)*Objetivos!$B$7 -> 0 | L6: =MAX(0,SUMIFS(Objetivos!$I$26:$I$45,Objetivos!$E$26:$E$45,B6,Objetivos!$C$26:$C$45,"Único",Objetivos!$B$26:$B$45,Objetivos!$A$19)+SUMPRODUCT(((Objetivos!$C$26:$C$45="Renta")+(Objetivos!$C$26:$C$45="Jubilación"))*(Objetivos!$B$26:$B$45=Objetivos!$A$19)*(B6>=Objetivos!$E$26:$E$45)*(B6<Objetivos!$E$26:$E$45+Objetivos!$H$26:$H$45)*Objetivos!$G$26:$G$45)*12*(1+Objetivos!$B$6)^B6-H6) -> 0 | M6: =IF(B6>=Objetivos!$B$11,0,IF(B6=1,Objetivos!$E$20*12+Objetivos!$C$20+Objetivos!$D$20,Objetivos!$E$20*12*(1+Objetivos!$B$9)^(B6-1))) -> 22920 | N6: =M6 -> 22920 | O6: =M6 -> 22920 | P6: =MIN(N6,SUMIFS(Objetivos!$I$26:$I$45,Objetivos!$E$26:$E$45,B6,Objetivos!$C$26:$C$45,"Único",Objetivos!$B$26:$B$45,Objetivos!$A$20)+SUMPRODUCT(((Objetivos!$C$26:$C$45="Renta")+(Objetivos!$C$26:$C$45="Jubilación"))*(Objetivos!$B$26:$B$45=Objetivos!$A$20)*(B6>=Objetivos!$E$26:$E$45)*(B6<Objetivos!$E$26:$E$45+Objetivos!$H$26:$H$45)*Objetivos!$G$26:$G$45)*12*(1+Objetivos!$B$6)^B6) -> 0 | Q6: =P6+IF(N6=0,0,P6*MAX(0,N6-O6)/N6)*Objetivos!$B$7 -> 0 | R6: =MAX(0,SUMIFS(Objetivos!$I$26:$I$45,Objetivos!$E$26:$E$45,B6,Objetivos!$C$26:$C$45,"Único",Objetivos!$B$26:$B$45,Objetivos!$A$20)+SUMPRODUCT(((Objetivos!$C$26:$C$45="Renta")+(Objetivos!$C$26:$C$45="Jubilación"))*(Objetivos!$B$26:$B$45=Objetivos!$A$20)*(B6>=Objetivos!$E$26:$E$45)*(B6<Objetivos!$E$26:$E$45+Objetivos!$H$26:$H$45)*Objetivos!$G$26:$G$45)*12*(1+Objetivos!$B$6)^B6-N6) -> 0 | S6: =IF(B6>=Objetivos!$B$11,0,IF(B6=1,Objetivos!$E$21*12+Objetivos!$C$21+Objetivos!$D$21,Objetivos!$E$21*12*(1+Objetivos!$B$9)^(B6-1))) -> 10800 | T6: =S6 -> 10800 | U6: =S6 -> 10800 | V6: =MIN(T6,SUMIFS(Objetivos!$I$26:$I$45,Objetivos!$E$26:$E$45,B6,Objetivos!$C$26:$C$45,"Único",Objetivos!$B$26:$B$45,Objetivos!$A$21)+SUMPRODUCT(((Objetivos!$C$26:$C$45="Renta")+(Objetivos!$C$26:$C$45="Jubilación"))*(Objetivos!$B$26:$B$45=Objetivos!$A$21)*(B6>=Objetivos!$E$26:$E$45)*(B6<Objetivos!$E$26:$E$45+Objetivos!$H$26:$H$45)*Objetivos!$G$26:$G$45)*12*(1+Objetivos!$B$6)^B6) -> 0 | W6: =V6+IF(T6=0,0,V6*MAX(0,T6-U6)/T6)*Objetivos!$B$7 -> 0 | X6: =MAX(0,SUMIFS(Objetivos!$I$26:$I$45,Objetivos!$E$26:$E$45,B6,Objetivos!$C$26:$C$45,"Único",Objetivos!$B$26:$B$45,Objetivos!$A$21)+SUMPRODUCT(((Objetivos!$C$26:$C$45="Renta")+(Objetivos!$C$26:$C$45="Jubilación"))*(Objetivos!$B$26:$B$45=Objetivos!$A$21)*(B6>=Objetivos!$E$26:$E$45)*(B6<Objetivos!$E$26:$E$45+Objetivos!$H$26:$H$45)*Objetivos!$G$26:$G$45)*12*(1+Objetivos!$B$6)^B6-T6) -> 0
A7: =Objetivos!$B$5+B7 -> 2028 | B7: 2 | C7: =H7+N7+T7 -> 54965.4 | D7: =(H7-MAX(0,H7-I7)*Objetivos!$B$7)+(N7-MAX(0,N7-O7)*Objetivos!$B$7)+(T7-MAX(0,T7-U7)*Objetivos!$B$7) -> 54485.844 | E7: =G7+M7+S7 -> 11505.6 | F7: =J7+P7+V7 -> 0 | G7: =IF(B7>=Objetivos!$B$11,0,IF(B7=1,Objetivos!$E$19*12+Objetivos!$C$19+Objetivos!$D$19,Objetivos!$E$19*12*(1+Objetivos!$B$9)^(B7-1))) -> 4651.2 | H7: =MAX(0,(H6-K6)*(1+Objetivos!$B$19)+G7) -> 12475.8 | I7: =MAX(0,I6-IF(H6=0,0,J6*I6/H6)+G7) -> 12211.2 | J7: =MIN(H7,SUMIFS(Objetivos!$I$26:$I$45,Objetivos!$E$26:$E$45,B7,Objetivos!$C$26:$C$45,"Único",Objetivos!$B$26:$B$45,Objetivos!$A$19)+SUMPRODUCT(((Objetivos!$C$26:$C$45="Renta")+(Objetivos!$C$26:$C$45="Jubilación"))*(Objetivos!$B$26:$B$45=Objetivos!$A$19)*(B7>=Objetivos!$E$26:$E$45)*(B7<Objetivos!$E$26:$E$45+Objetivos!$H$26:$H$45)*Objetivos!$G$26:$G$45)*12*(1+Objetivos!$B$6)^B7) -> 0 | K7: =J7+IF(H7=0,0,J7*MAX(0,H7-I7)/H7)*Objetivos!$B$7 -> 0 | L7: =MAX(0,SUMIFS(Objetivos!$I$26:$I$45,Objetivos!$E$26:$E$45,B7,Objetivos!$C$26:$C$45,"Único",Objetivos!$B$26:$B$45,Objetivos!$A$19)+SUMPRODUCT(((Objetivos!$C$26:$C$45="Renta")+(Objetivos!$C$26:$C$45="Jubilación"))*(Objetivos!$B$26:$B$45=Objetivos!$A$19)*(B7>=Objetivos!$E$26:$E$45)*(B7<Objetivos!$E$26:$E$45+Objetivos!$H$26:$H$45)*Objetivos!$G$26:$G$45)*12*(1+Objetivos!$B$6)^B7-H7) -> 0 | M7: =IF(B7>=Objetivos!$B$11,0,IF(B7=1,Objetivos!$E$20*12+Objetivos!$C$20+Objetivos!$D$20,Objetivos!$E$20*12*(1+Objetivos!$B$9)^(B7-1))) -> 5018.4 | N7: =MAX(0,(N6-Q6)*(1+Objetivos!$B$20)+M7) -> 29313.6 | O7: =MAX(0,O6-IF(N6=0,0,P6*O6/N6)+M7) -> 27938.4 | P7: =MIN(N7,SUMIFS(Objetivos!$I$26:$I$45,Objetivos!$E$26:$E$45,B7,Objetivos!$C$26:$C$45,"Único",Objetivos!$B$26:$B$45,Objetivos!$A$20)+SUMPRODUCT(((Objetivos!$C$26:$C$45="Renta")+(Objetivos!$C$26:$C$45="Jubilación"))*(Objetivos!$B$26:$B$45=Objetivos!$A$20)*(B7>=Objetivos!$E$26:$E$45)*(B7<Objetivos!$E$26:$E$45+Objetivos!$H$26:$H$45)*Objetivos!$G$26:$G$45)*12*(1+Objetivos!$B$6)^B7) -> 0 | Q7: =P7+IF(N7=0,0,P7*MAX(0,N7-O7)/N7)*Objetivos!$B$7 -> 0 | R7: =MAX(0,SUMIFS(Objetivos!$I$26:$I$45,Objetivos!$E$26:$E$45,B7,Objetivos!$C$26:$C$45,"Único",Objetivos!$B$26:$B$45,Objetivos!$A$20)+SUMPRODUCT(((Objetivos!$C$26:$C$45="Renta")+(Objetivos!$C$26:$C$45="Jubilación"))*(Objetivos!$B$26:$B$45=Objetivos!$A$20)*(B7>=Objetivos!$E$26:$E$45)*(B7<Objetivos!$E$26:$E$45+Objetivos!$H$26:$H$45)*Objetivos!$G$26:$G$45)*12*(1+Objetivos!$B$6)^B7-N7) -> 0 | S7: =IF(B7>=Objetivos!$B$11,0,IF(B7=1,Objetivos!$E$21*12+Objetivos!$C$21+Objetivos!$D$21,Objetivos!$E$21*12*(1+Objetivos!$B$9)^(B7-1))) -> 1836 | T7: =MAX(0,(T6-W6)*(1+Objetivos!$B$21)+S7) -> 13176 | U7: =MAX(0,U6-IF(T6=0,0,V6*U6/T6)+S7) -> 12636 | V7: =MIN(T7,SUMIFS(Objetivos!$I$26:$I$45,Objetivos!$E$26:$E$45,B7,Objetivos!$C$26:$C$45,"Único",Objetivos!$B$26:$B$45,Objetivos!$A$21)+SUMPRODUCT(((Objetivos!$C$26:$C$45="Renta")+(Objetivos!$C$26:$C$45="Jubilación"))*(Objetivos!$B$26:$B$45=Objetivos!$A$21)*(B7>=Objetivos!$E$26:$E$45)*(B7<Objetivos!$E$26:$E$45+Objetivos!$H$26:$H$45)*Objetivos!$G$26:$G$45)*12*(1+Objetivos!$B$6)^B7) -> 0 | W7: =V7+IF(T7=0,0,V7*MAX(0,T7-U7)/T7)*Objetivos!$B$7 -> 0 | X7: =MAX(0,SUMIFS(Objetivos!$I$26:$I$45,Objetivos!$E$26:$E$45,B7,Objetivos!$C$26:$C$45,"Único",Objetivos!$B$26:$B$45,Objetivos!$A$21)+SUMPRODUCT(((Objetivos!$C$26:$C$45="Renta")+(Objetivos!$C$26:$C$45="Jubilación"))*(Objetivos!$B$26:$B$45=Objetivos!$A$21)*(B7>=Objetivos!$E$26:$E$45)*(B7<Objetivos!$E$26:$E$45+Objetivos!$H$26:$H$45)*Objetivos!$G$26:$G$45)*12*(1+Objetivos!$B$6)^B7-T7) -> 0
A8: =Objetivos!$B$5+B8 -> 2029 | B8: 3 | C8: =H8+N8+T8 -> 69555.381 | D8: =(H8-MAX(0,H8-I8)*Objetivos!$B$7)+(N8-MAX(0,N8-O8)*Objetivos!$B$7)+(T8-MAX(0,T8-U8)*Objetivos!$B$7) -> 68447.886 | E8: =G8+M8+S8 -> 11735.712 | F8: =J8+P8+V8 -> 0 | G8: =IF(B8>=Objetivos!$B$11,0,IF(B8=1,Objetivos!$E$19*12+Objetivos!$C$19+Objetivos!$D$19,Objetivos!$E$19*12*(1+Objetivos!$B$9)^(B8-1))) -> 4744.224 | H8: =MAX(0,(H7-K7)*(1+Objetivos!$B$19)+G8) -> 17656.677 | I8: =MAX(0,I7-IF(H7=0,0,J7*I7/H7)+G8) -> 16955.424 | J8: =MIN(H8,SUMIFS(Objetivos!$I$26:$I$45,Objetivos!$E$26:$E$45,B8,Objetivos!$C$26:$C$45,"Único",Objetivos!$B$26:$B$45,Objetivos!$A$19)+SUMPRODUCT(((Objetivos!$C$26:$C$45="Renta")+(Objetivos!$C$26:$C$45="Jubilación"))*(Objetivos!$B$26:$B$45=Objetivos!$A$19)*(B8>=Objetivos!$E$26:$E$45)*(B8<Objetivos!$E$26:$E$45+Objetivos!$H$26:$H$45)*Objetivos!$G$26:$G$45)*12*(1+Objetivos!$B$6)^B8) -> 0 | K8: =J8+IF(H8=0,0,J8*MAX(0,H8-I8)/H8)*Objetivos!$B$7 -> 0 | L8: =MAX(0,SUMIFS(Objetivos!$I$26:$I$45,Objetivos!$E$26:$E$45,B8,Objetivos!$C$26:$C$45,"Único",Objetivos!$B$26:$B$45,Objetivos!$A$19)+SUMPRODUCT(((Objetivos!$C$26:$C$45="Renta")+(Objetivos!$C$26:$C$45="Jubilación"))*(Objetivos!$B$26:$B$45=Objetivos!$A$19)*(B8>=Objetivos!$E$26:$E$45)*(B8<Objetivos!$E$26:$E$45+Objetivos!$H$26:$H$45)*Objetivos!$G$26:$G$45)*12*(1+Objetivos!$B$6)^B8-H8) -> 0 | M8: =IF(B8>=Objetivos!$B$11,0,IF(B8=1,Objetivos!$E$20*12+Objetivos!$C$20+Objetivos!$D$20,Objetivos!$E$20*12*(1+Objetivos!$B$9)^(B8-1))) -> 5118.768 | N8: =MAX(0,(N7-Q7)*(1+Objetivos!$B$20)+M8) -> 36191.184 | O8: =MAX(0,O7-IF(N7=0,0,P7*O7/N7)+M8) -> 33057.168 | P8: =MIN(N8,SUMIFS(Objetivos!$I$26:$I$45,Objetivos!$E$26:$E$45,B8,Objetivos!$C$26:$C$45,"Único",Objetivos!$B$26:$B$45,Objetivos!$A$20)+SUMPRODUCT(((Objetivos!$C$26:$C$45="Renta")+(Objetivos!$C$26:$C$45="Jubilación"))*(Objetivos!$B$26:$B$45=Objetivos!$A$20)*(B8>=Objetivos!$E$26:$E$45)*(B8<Objetivos!$E$26:$E$45+Objetivos!$H$26:$H$45)*Objetivos!$G$26:$G$45)*12*(1+Objetivos!$B$6)^B8) -> 0 | Q8: =P8+IF(N8=0,0,P8*MAX(0,N8-O8)/N8)*Objetivos!$B$7 -> 0 | R8: =MAX(0,SUMIFS(Objetivos!$I$26:$I$45,Objetivos!$E$26:$E$45,B8,Objetivos!$C$26:$C$45,"Único",Objetivos!$B$26:$B$45,Objetivos!$A$20)+SUMPRODUCT(((Objetivos!$C$26:$C$45="Renta")+(Objetivos!$C$26:$C$45="Jubilación"))*(Objetivos!$B$26:$B$45=Objetivos!$A$20)*(B8>=Objetivos!$E$26:$E$45)*(B8<Objetivos!$E$26:$E$45+Objetivos!$H$26:$H$45)*Objetivos!$G$26:$G$45)*12*(1+Objetivos!$B$6)^B8-N8) -> 0 | S8: =IF(B8>=Objetivos!$B$11,0,IF(B8=1,Objetivos!$E$21*12+Objetivos!$C$21+Objetivos!$D$21,Objetivos!$E$21*12*(1+Objetivos!$B$9)^(B8-1))) -> 1872.72 | T8: =MAX(0,(T7-W7)*(1+Objetivos!$B$21)+S8) -> 15707.52 | U8: =MAX(0,U7-IF(T7=0,0,V7*U7/T7)+S8) -> 14508.72 | V8: =MIN(T8,SUMIFS(Objetivos!$I$26:$I$45,Objetivos!$E$26:$E$45,B8,Objetivos!$C$26:$C$45,"Único",Objetivos!$B$26:$B$45,Objetivos!$A$21)+SUMPRODUCT(((Objetivos!$C$26:$C$45="Renta")+(Objetivos!$C$26:$C$45="Jubilación"))*(Objetivos!$B$26:$B$45=Objetivos!$A$21)*(B8>=Objetivos!$E$26:$E$45)*(B8<Objetivos!$E$26:$E$45+Objetivos!$H$26:$H$45)*Objetivos!$G$26:$G$45)*12*(1+Objetivos!$B$6)^B8) -> 0 | W8: =V8+IF(T8=0,0,V8*MAX(0,T8-U8)/T8)*Objetivos!$B$7 -> 0 | X8: =MAX(0,SUMIFS(Objetivos!$I$26:$I$45,Objetivos!$E$26:$E$45,B8,Objetivos!$C$26:$C$45,"Único",Objetivos!$B$26:$B$45,Objetivos!$A$21)+SUMPRODUCT(((Objetivos!$C$26:$C$45="Renta")+(Objetivos!$C$26:$C$45="Jubilación"))*(Objetivos!$B$26:$B$45=Objetivos!$A$21)*(B8>=Objetivos!$E$26:$E$45)*(B8<Objetivos!$E$26:$E$45+Objetivos!$H$26:$H$45)*Objetivos!$G$26:$G$45)*12*(1+Objetivos!$B$6)^B8-T8) -> 0
A9: =Objetivos!$B$5+B9 -> 2030 | B9: 4 | C9: =H9+N9+T9 -> 85100.638 | D9: =(H9-MAX(0,H9-I9)*Objetivos!$B$7)+(N9-MAX(0,N9-O9)*Objetivos!$B$7)+(T9-MAX(0,T9-U9)*Objetivos!$B$7) -> 83206.68 | E9: =G9+M9+S9 -> 11970.426 | F9: =J9+P9+V9 -> 0 | G9: =IF(B9>=Objetivos!$B$11,0,IF(B9=1,Objetivos!$E$19*12+Objetivos!$C$19+Objetivos!$D$19,Objetivos!$E$19*12*(1+Objetivos!$B$9)^(B9-1))) -> 4839.1085 | H9: =MAX(0,(H8-K8)*(1+Objetivos!$B$19)+G9) -> 23113.769 | I9: =MAX(0,I8-IF(H8=0,0,J8*I8/H8)+G9) -> 21794.532 | J9: =MIN(H9,SUMIFS(Objetivos!$I$26:$I$45,Objetivos!$E$26:$E$45,B9,Objetivos!$C$26:$C$45,"Único",Objetivos!$B$26:$B$45,Objetivos!$A$19)+SUMPRODUCT(((Objetivos!$C$26:$C$45="Renta")+(Objetivos!$C$26:$C$45="Jubilación"))*(Objetivos!$B$26:$B$45=Objetivos!$A$19)*(B9>=Objetivos!$E$26:$E$45)*(B9<Objetivos!$E$26:$E$45+Objetivos!$H$26:$H$45)*Objetivos!$G$26:$G$45)*12*(1+Objetivos!$B$6)^B9) -> 0 | K9: =J9+IF(H9=0,0,J9*MAX(0,H9-I9)/H9)*Objetivos!$B$7 -> 0 | L9: =MAX(0,SUMIFS(Objetivos!$I$26:$I$45,Objetivos!$E$26:$E$45,B9,Objetivos!$C$26:$C$45,"Único",Objetivos!$B$26:$B$45,Objetivos!$A$19)+SUMPRODUCT(((Objetivos!$C$26:$C$45="Renta")+(Objetivos!$C$26:$C$45="Jubilación"))*(Objetivos!$B$26:$B$45=Objetivos!$A$19)*(B9>=Objetivos!$E$26:$E$45)*(B9<Objetivos!$E$26:$E$45+Objetivos!$H$26:$H$45)*Objetivos!$G$26:$G$45)*12*(1+Objetivos!$B$6)^B9-H9) -> 0 | M9: =IF(B9>=Objetivos!$B$11,0,IF(B9=1,Objetivos!$E$20*12+Objetivos!$C$20+Objetivos!$D$20,Objetivos!$E$20*12*(1+Objetivos!$B$9)^(B9-1))) -> 5221.1434 | N9: =MAX(0,(N8-Q8)*(1+Objetivos!$B$20)+M9) -> 43583.798 | O9: =MAX(0,O8-IF(N8=0,0,P8*O8/N8)+M9) -> 38278.311 | P9: =MIN(N9,SUMIFS(Objetivos!$I$26:$I$45,Objetivos!$E$26:$E$45,B9,Objetivos!$C$26:$C$45,"Único",Objetivos!$B$26:$B$45,Objetivos!$A$20)+SUMPRODUCT(((Objetivos!$C$26:$C$45="Renta")+(Objetivos!$C$26:$C$45="Jubilación"))*(Objetivos!$B$26:$B$45=Objetivos!$A$20)*(B9>=Objetivos!$E$26:$E$45)*(B9<Objetivos!$E$26:$E$45+Objetivos!$H$26:$H$45)*Objetivos!$G$26:$G$45)*12*(1+Objetivos!$B$6)^B9) -> 0 | Q9: =P9+IF(N9=0,0,P9*MAX(0,N9-O9)/N9)*Objetivos!$B$7 -> 0 | R9: =MAX(0,SUMIFS(Objetivos!$I$26:$I$45,Objetivos!$E$26:$E$45,B9,Objetivos!$C$26:$C$45,"Único",Objetivos!$B$26:$B$45,Objetivos!$A$20)+SUMPRODUCT(((Objetivos!$C$26:$C$45="Renta")+(Objetivos!$C$26:$C$45="Jubilación"))*(Objetivos!$B$26:$B$45=Objetivos!$A$20)*(B9>=Objetivos!$E$26:$E$45)*(B9<Objetivos!$E$26:$E$45+Objetivos!$H$26:$H$45)*Objetivos!$G$26:$G$45)*12*(1+Objetivos!$B$6)^B9-N9) -> 0 | S9: =IF(B9>=Objetivos!$B$11,0,IF(B9=1,Objetivos!$E$21*12+Objetivos!$C$21+Objetivos!$D$21,Objetivos!$E$21*12*(1+Objetivos!$B$9)^(B9-1))) -> 1910.1744 | T9: =MAX(0,(T8-W8)*(1+Objetivos!$B$21)+S9) -> 18403.07 | U9: =MAX(0,U8-IF(T8=0,0,V8*U8/T8)+S9) -> 16418.894 | V9: =MIN(T9,SUMIFS(Objetivos!$I$26:$I$45,Objetivos!$E$26:$E$45,B9,Objetivos!$C$26:$C$45,"Único",Objetivos!$B$26:$B$45,Objetivos!$A$21)+SUMPRODUCT(((Objetivos!$C$26:$C$45="Renta")+(Objetivos!$C$26:$C$45="Jubilación"))*(Objetivos!$B$26:$B$45=Objetivos!$A$21)*(B9>=Objetivos!$E$26:$E$45)*(B9<Objetivos!$E$26:$E$45+Objetivos!$H$26:$H$45)*Objetivos!$G$26:$G$45)*12*(1+Objetivos!$B$6)^B9) -> 0 | W9: =V9+IF(T9=0,0,V9*MAX(0,T9-U9)/T9)*Objetivos!$B$7 -> 0 | X9: =MAX(0,SUMIFS(Objetivos!$I$26:$I$45,Objetivos!$E$26:$E$45,B9,Objetivos!$C$26:$C$45,"Único",Objetivos!$B$26:$B$45,Objetivos!$A$21)+SUMPRODUCT(((Objetivos!$C$26:$C$45="Renta")+(Objetivos!$C$26:$C$45="Jubilación"))*(Objetivos!$B$26:$B$45=Objetivos!$A$21)*(B9>=Objetivos!$E$26:$E$45)*(B9<Objetivos!$E$26:$E$45+Objetivos!$H$26:$H$45)*Objetivos!$G$26:$G$45)*12*(1+Objetivos!$B$6)^B9-T9) -> 0
